Workbook
Name HoldoutStart: 'Forecast validation'!$B$31
Name ValidationStart: 'Forecast validation'!$B$30

Sheet Read me
A2: Synthetic maintenance labor dataset
A4: Purpose | B4: Estimate work-package labor and forecast capacity using a realistic but entirely simulated shop.
A5: Period | B5: 2024-01-01 through 2025-12-30 request dates
A6: Population | B6: 2,400 simulated work packages across 14 fictional test aircraft and 75 technicians.
A7: Source | B7: Original synthetic data generated with a fixed random seed (20260928). No aircraft manufacturer or regulatory agency records.
A8: Unit of prediction | B8: Total actual labor hours per work package at intake.
A9: Prediction-time fields | B9: Aircraft, request date, due date, task type/class, required skill, complexity, priority, part requirement, estimated hours.
A10: Outcome fields | B10: Completion date, actual labor hours and labor entries. Keep out of intake-time features.
A11: Leakage warning | B11: Repeat work, parts arrival/delay and disruptions are realized after intake; exclude them from initial estimates.
A12: Labor relationship | B12: Labor entries sum to actual labor hours for each work package, subject to 0.1-hour rounding.
A13: Parts relationship | B13: One part record exists for each package marked part required.
A14: Disruption relationship | B14: Records reflect part delays or operational events; some packages have neither.
A15: Generation logic | B15: Task baseline × complexity × aircraft age × season; realized hours add random variation, rework and disruptions.
... A40: Calendar and availability | B40: Historical bookings include weekends. The 12-hour technician-day cap is a simulation constraint, not a verified shift calendar. Shift labels and availability factors do not prove day-level availability. Earlier reassigned bookings assume same-skill staff and task readiness; detailed qualifications, absence calendars and task dependencies are not modeled.

Sheet Dashboard
A2: Labor forecast and capacity dashboard
A3: Aerospace maintenance planning simulation. Synthetic data; staffing, costs and recovery options are hypothetical.
A5: Headline | B5: Value
A6: Forecast method selected | B6: ='Weekly forecast'!F10 -> Same week last year
A7: Independent weekly test WMAPE | B7: =INDEX('Weekly forecast'!K5:K8,'Weekly forecast'!F11) -> 0.26662927
A8: Independent weekly test bias | B8: =INDEX('Weekly forecast'!L5:L8,'Weekly forecast'!F11) -> -0.064702389
A9: Forecast window starts | B9: ='Capacity outlook'!B5 -> 46027
A10: Forecast incoming hours | B10: ='Capacity outlook'!B7 -> 4334.6
A11: Plus open backlog | B11: ='Capacity outlook'!B8 -> 521.62978
A12: Allocated capacity | B12: ='Capacity outlook'!B10 -> 4661.9523
A13: Overall utilization | B13: ='Capacity outlook'!B11 -> 1.041673
A14: Skills short or tight | B14: =COUNTIFS('Capacity outlook'!K18:K23,"Short")+COUNTIFS('Capacity outlook'!K18:K23,"Tight") -> 6
A15: Most loaded skill | B15: =INDEX('Capacity outlook'!A18:A23,MATCH(MAX('Capacity outlook'!H18:H23),'Capacity outlook'!H18:H23,0)) -> Avionics
A16: Most loaded skill utilization | B16: =MAX('Capacity outlook'!H18:H23) -> 1.204858
A17: On-time completion rate | B17: ='Schedule performance'!B7 -> 0.51541667
A19: Job-level estimate bias | B19: Original estimate | C19: Calibrated forecast
A20: Validation H1 2025 | B20: =(SUMIFS(tblWorkPackages[Estimated labor hours],tblWorkPackages[Time split],"Validation H1")-SUMIFS(tblWorkPackages[Actual labor hours],tblWorkPackages[Time split],"Validation H1"))/SUMIFS(tblWorkPackages[Actual labor hours],tblWorkPackages[Time split],"Validation H1") -> -0.071884858 | C20: =(SUMIFS(tblWorkPackages[Calibrated forecast hours],tblWorkPackages[Time split],"Validation H1")-SUMIFS(tblWorkPackages[Actual labor hours],tblWorkPackages[Time split],"Validation H1"))/SUMIFS(tblWorkPackages[Actual labor hours],tblWorkPackages[Time split],"Validation H1") -> -0.023018694
A21: Holdout H2 2025 | B21: =(SUMIFS(tblWorkPackages[Estimated labor hours],tblWorkPackages[Time split],"Holdout H2")-SUMIFS(tblWorkPackages[Actual labor hours],tblWorkPackages[Time split],"Holdout H2"))/SUMIFS(tblWorkPackages[Actual labor hours],tblWorkPackages[Time split],"Holdout H2") -> -0.074787437 | C21: =(SUMIFS(tblWorkPackages[Calibrated forecast hours],tblWorkPackages[Time split],"Holdout H2")-SUMIFS(tblWorkPackages[Actual labor hours],tblWorkPackages[Time split],"Holdout H2"))/SUMIFS(tblWorkPackages[Actual labor hours],tblWorkPackages[Time split],"Holdout H2") -> -0.0060552481
A22: Negative bias means estimates ran below actual hours. Calibration adds the task-level adjustment learned from earlier work.

Sheet Work packages
A1: Work package ID | B1: Aircraft ID | C1: Request date | D1: Due date | E1: Task type | F1: Work class | G1: Required skill | H1: Complexity (1-4) | I1: Priority | J1: Repeat work (0/1) | K1: Part required (0/1) | L1: Estimated labor hours | M1: Completion date | N1: Actual labor hours | O1: Request week (Monday) | P1: Absolute estimate error | Q1: Above estimate (0/1) | R1: Actual less estimate | S1: Time split | T1: Calibrated forecast hours | U1: Calibrated absolute error | V1: Planning forecast hours | W1: Request date serial | X1: Due date serial | Y1: Completion date serial | Z1: First labor date | AA1: Last labor date | AB1: Late (0/1) | AC1: Days late | AD1: Queue days | AE1: Work span days | AF1: Closeout days | AG1: Flow days | AH1: Part delay days | AI1: Disruption type | AJ1: Due month
A2: WP-00001 | B2: FT-03 | C2: 2025-05-03 | D2: 2025-05-16 | E2: Flight control inspection | F2: Inspection | G2: Airframe | H2: 3 | I2: Routine | J2: 0 | K2: 0 | L2: 11 | M2: 2025-05-14 | N2: 10.8 | O2: =TEXT(tblWorkPackages[[#This Row],[Request date serial]]-WEEKDAY(tblWorkPackages[[#This Row],[Request date serial]],3),"yyyy-mm-dd") -> 2025-04-28 | P2: =ABS(tblWorkPackages[[#This Row],[Actual labor hours]]-tblWorkPackages[[#This Row],[Estimated labor hours]]) -> 0.2 | Q2: =IF(tblWorkPackages[[#This Row],[Actual labor hours]]>tblWorkPackages[[#This Row],[Estimated labor hours]],1,0) -> 0 | R2: =tblWorkPackages[[#This Row],[Actual labor hours]]-tblWorkPackages[[#This Row],[Estimated labor hours]] -> -0.2 | S2: =IF(tblWorkPackages[[#This Row],[Request date serial]]<ValidationStart,"Train 2024",IF(tblWorkPackages[[#This Row],[Request date serial]]<HoldoutStart,"Validation H1","Holdout H2")) -> Validation H1 | T2: =IF(tblWorkPackages[[#This Row],[Time split]]="Train 2024","",tblWorkPackages[[#This Row],[Estimated labor hours]]+VLOOKUP(tblWorkPackages[[#This Row],[Task type]],'Forecast validation'!$A$14:$E$25,IF(tblWorkPackages[[#This Row],[Time split]]="Validation H1",4,5),FALSE())) -> 11.475641 | U2: =IF(tblWorkPackages[[#This Row],[Calibrated forecast hours]]="","",ABS(tblWorkPackages[[#This Row],[Actual labor hours]]-tblWorkPackages[[#This Row],[Calibrated forecast hours]])) -> 0.67564103 | V2: =IF(tblWorkPackages[[#This Row],[Time split]]="Train 2024",tblWorkPackages[[#This Row],[Estimated labor hours]],tblWorkPackages[[#This Row],[Calibrated forecast hours]]) -> 11.475641 | W2: =DATEVALUE(tblWorkPackages[[#This Row],[Request date]]) -> 45780 | X2: =DATEVALUE(tblWorkPackages[[#This Row],[Due date]]) -> 45793 | Y2: =DATEVALUE(tblWorkPackages[[#This Row],[Completion date]]) -> 45791 | Z2: =_xlfn.MINIFS(tblLaborEntries[Work date serial],tblLaborEntries[Work package ID],tblWorkPackages[[#This Row],[Work package ID]]) -> 45789 | AA2: =_xlfn.MAXIFS(tblLaborEntries[Work date serial],tblLaborEntries[Work package ID],tblWorkPackages[[#This Row],[Work package ID]]) -> 45791 | AB2: =IF(tblWorkPackages[[#This Row],[Completion date serial]]>tblWorkPackages[[#This Row],[Due date serial]],1,0) -> 0 | AC2: =MAX(0,tblWorkPackages[[#This Row],[Completion date serial]]-tblWorkPackages[[#This Row],[Due date serial]]) -> 0 | AD2: =tblWorkPackages[[#This Row],[First labor date]]-tblWorkPackages[[#This Row],[Request date serial]] -> 9 | AE2: =tblWorkPackages[[#This Row],[Last labor date]]-tblWorkPackages[[#This Row],[First labor date]] -> 2 | AF2: =tblWorkPackages[[#This Row],[Completion date serial]]-tblWorkPackages[[#This Row],[Last labor date]] -> 0 | AG2: =tblWorkPackages[[#This Row],[Completion date serial]]-tblWorkPackages[[#This Row],[Request date serial]] -> 11 | AH2: =IFERROR(INDEX(tblParts[Delay days],MATCH(tblWorkPackages[[#This Row],[Work package ID]],tblParts[Work package ID],0)),0) -> 0 | AI2: =IFERROR(INDEX(tblDisruptions[Event type],MATCH(tblWorkPackages[[#This Row],[Work package ID]],tblDisruptions[Work package ID],0)),"None") -> None | AJ2: =TEXT(tblWorkPackages[[#This Row],[Due date serial]],"yyyy-mm") -> 2025-05
A3: WP-00002 | B3: FT-06 | C3: 2025-09-05 | D3: 2025-09-18 | E3: Instrumentation installation | F3: Modification | G3: Avionics | H3: 1 | I3: Routine | J3: 0 | K3: 0 | L3: 8.1 | M3: 2025-09-08 | N3: 6.9 | O3: =TEXT(tblWorkPackages[[#This Row],[Request date serial]]-WEEKDAY(tblWorkPackages[[#This Row],[Request date serial]],3),"yyyy-mm-dd") -> 2025-09-01 | P3: =ABS(tblWorkPackages[[#This Row],[Actual labor hours]]-tblWorkPackages[[#This Row],[Estimated labor hours]]) -> 1.2 | Q3: =IF(tblWorkPackages[[#This Row],[Actual labor hours]]>tblWorkPackages[[#This Row],[Estimated labor hours]],1,0) -> 0 | R3: =tblWorkPackages[[#This Row],[Actual labor hours]]-tblWorkPackages[[#This Row],[Estimated labor hours]] -> -1.2 | S3: =IF(tblWorkPackages[[#This Row],[Request date serial]]<ValidationStart,"Train 2024",IF(tblWorkPackages[[#This Row],[Request date serial]]<HoldoutStart,"Validation H1","Holdout H2")) -> Holdout H2 | T3: =IF(tblWorkPackages[[#This Row],[Time split]]="Train 2024","",tblWorkPackages[[#This Row],[Estimated labor hours]]+VLOOKUP(tblWorkPackages[[#This Row],[Task type]],'Forecast validation'!$A$14:$E$25,IF(tblWorkPackages[[#This Row],[Time split]]="Validation H1",4,5),FALSE())) -> 9.0207547 | U3: =IF(tblWorkPackages[[#This Row],[Calibrated forecast hours]]="","",ABS(tblWorkPackages[[#This Row],[Actual labor hours]]-tblWorkPackages[[#This Row],[Calibrated forecast hours]])) -> 2.1207547 | V3: =IF(tblWorkPackages[[#This Row],[Time split]]="Train 2024",tblWorkPackages[[#This Row],[Estimated labor hours]],tblWorkPackages[[#This Row],[Calibrated forecast hours]]) -> 9.0207547 | W3: =DATEVALUE(tblWorkPackages[[#This Row],[Request date]]) -> 45905 | X3: =DATEVALUE(tblWorkPackages[[#This Row],[Due date]]) -> 45918 | Y3: =DATEVALUE(tblWorkPackages[[#This Row],[Completion date]]) -> 45908 | Z3: =_xlfn.MINIFS(tblLaborEntries[Work date serial],tblLaborEntries[Work package ID],tblWorkPackages[[#This Row],[Work package ID]]) -> 45907 | AA3: =_xlfn.MAXIFS(tblLaborEntries[Work date serial],tblLaborEntries[Work package ID],tblWorkPackages[[#This Row],[Work package ID]]) -> 45907 | AB3: =IF(tblWorkPackages[[#This Row],[Completion date serial]]>tblWorkPackages[[#This Row],[Due date serial]],1,0) -> 0 | AC3: =MAX(0,tblWorkPackages[[#This Row],[Completion date serial]]-tblWorkPackages[[#This Row],[Due date serial]]) -> 0 | AD3: =tblWorkPackages[[#This Row],[First labor date]]-tblWorkPackages[[#This Row],[Request date serial]] -> 2 | AE3: =tblWorkPackages[[#This Row],[Last labor date]]-tblWorkPackages[[#This Row],[First labor date]] -> 0 | AF3: =tblWorkPackages[[#This Row],[Completion date serial]]-tblWorkPackages[[#This Row],[Last labor date]] -> 1 | AG3: =tblWorkPackages[[#This Row],[Completion date serial]]-tblWorkPackages[[#This Row],[Request date serial]] -> 3 | AH3: =IFERROR(INDEX(tblParts[Delay days],MATCH(tblWorkPackages[[#This Row],[Work package ID]],tblParts[Work package ID],0)),0) -> 0 | AI3: =IFERROR(INDEX(tblDisruptions[Event type],MATCH(tblWorkPackages[[#This Row],[Work package ID]],tblDisruptions[Work package ID],0)),"None") -> None | AJ3: =TEXT(tblWorkPackages[[#This Row],[Due date serial]],"yyyy-mm") -> 2025-09
A4: WP-00003 | B4: FT-02 | C4: 2024-01-31 | D4: 2024-02-02 | E4: Hydraulic leak diagnosis | F4: Corrective | G4: Hydraulics | H4: 4 | I4: Urgent | J4: 0 | K4: 1 | L4: 19.1 | M4: 2024-02-26 | N4: 14.7 | O4: =TEXT(tblWorkPackages[[#This Row],[Request date serial]]-WEEKDAY(tblWorkPackages[[#This Row],[Request date serial]],3),"yyyy-mm-dd") -> 2024-01-29 | P4: =ABS(tblWorkPackages[[#This Row],[Actual labor hours]]-tblWorkPackages[[#This Row],[Estimated labor hours]]) -> 4.4 | Q4: =IF(tblWorkPackages[[#This Row],[Actual labor hours]]>tblWorkPackages[[#This Row],[Estimated labor hours]],1,0) -> 0 | R4: =tblWorkPackages[[#This Row],[Actual labor hours]]-tblWorkPackages[[#This Row],[Estimated labor hours]] -> -4.4 | S4: =IF(tblWorkPackages[[#This Row],[Request date serial]]<ValidationStart,"Train 2024",IF(tblWorkPackages[[#This Row],[Request date serial]]<HoldoutStart,"Validation H1","Holdout H2")) -> Train 2024 | T4: =IF(tblWorkPackages[[#This Row],[Time split]]="Train 2024","",tblWorkPackages[[#This Row],[Estimated labor hours]]+VLOOKUP(tblWorkPackages[[#This Row],[Task type]],'Forecast validation'!$A$14:$E$25,IF(tblWorkPackages[[#This Row],[Time split]]="Validation H1",4,5),FALSE())) | U4: =IF(tblWorkPackages[[#This Row],[Calibrated forecast hours]]="","",ABS(tblWorkPackages[[#This Row],[Actual labor hours]]-tblWorkPackages[[#This Row],[Calibrated forecast hours]])) | V4: =IF(tblWorkPackages[[#This Row],[Time split]]="Train 2024",tblWorkPackages[[#This Row],[Estimated labor hours]],tblWorkPackages[[#This Row],[Calibrated forecast hours]]) -> 19.1 | W4: =DATEVALUE(tblWorkPackages[[#This Row],[Request date]]) -> 45322 | X4: =DATEVALUE(tblWorkPackages[[#This Row],[Due date]]) -> 45324 | Y4: =DATEVALUE(tblWorkPackages[[#This Row],[Completion date]]) -> 45348 | Z4: =_xlfn.MINIFS(tblLaborEntries[Work date serial],tblLaborEntries[Work package ID],tblWorkPackages[[#This Row],[Work package ID]]) -> 45345 | AA4: =_xlfn.MAXIFS(tblLaborEntries[Work date serial],tblLaborEntries[Work package ID],tblWorkPackages[[#This Row],[Work package ID]]) -> 45346 | AB4: =IF(tblWorkPackages[[#This Row],[Completion date serial]]>tblWorkPackages[[#This Row],[Due date serial]],1,0) -> 1 | AC4: =MAX(0,tblWorkPackages[[#This Row],[Completion date serial]]-tblWorkPackages[[#This Row],[Due date serial]]) -> 24 | AD4: =tblWorkPackages[[#This Row],[First labor date]]-tblWorkPackages[[#This Row],[Request date serial]] -> 23 | AE4: =tblWorkPackages[[#This Row],[Last labor date]]-tblWorkPackages[[#This Row],[First labor date]] -> 1 | AF4: =tblWorkPackages[[#This Row],[Completion date serial]]-tblWorkPackages[[#This Row],[Last labor date]] -> 2 | AG4: =tblWorkPackages[[#This Row],[Completion date serial]]-tblWorkPackages[[#This Row],[Request date serial]] -> 26 | AH4: =IFERROR(INDEX(tblParts[Delay days],MATCH(tblWorkPackages[[#This Row],[Work package ID]],tblParts[Work package ID],0)),0) -> 0 | AI4: =IFERROR(INDEX(tblDisruptions[Event type],MATCH(tblWorkPackages[[#This Row],[Work package ID]],tblDisruptions[Work package ID],0)),"None") -> None | AJ4: =TEXT(tblWorkPackages[[#This Row],[Due date serial]],"yyyy-mm") -> 2024-02
A5: WP-00004 | B5: FT-04 | C5: 2024-08-23 | D5: 2024-08-25 | E5: Fuel system inspection | F5: Inspection | G5: Powerplant | H5: 2 | I5: Urgent | J5: 1 | K5: 0 | L5: 9.4 | M5: 2024-08-31 | N5: 12.9 | O5: =TEXT(tblWorkPackages[[#This Row],[Request date serial]]-WEEKDAY(tblWorkPackages[[#This Row],[Request date serial]],3),"yyyy-mm-dd") -> 2024-08-19 | P5: =ABS(tblWorkPackages[[#This Row],[Actual labor hours]]-tblWorkPackages[[#This Row],[Estimated labor hours]]) -> 3.5 | Q5: =IF(tblWorkPackages[[#This Row],[Actual labor hours]]>tblWorkPackages[[#This Row],[Estimated labor hours]],1,0) -> 1 | R5: =tblWorkPackages[[#This Row],[Actual labor hours]]-tblWorkPackages[[#This Row],[Estimated labor hours]] -> 3.5 | S5: =IF(tblWorkPackages[[#This Row],[Request date serial]]<ValidationStart,"Train 2024",IF(tblWorkPackages[[#This Row],[Request date serial]]<HoldoutStart,"Validation H1","Holdout H2")) -> Train 2024 | T5: =IF(tblWorkPackages[[#This Row],[Time split]]="Train 2024","",tblWorkPackages[[#This Row],[Estimated labor hours]]+VLOOKUP(tblWorkPackages[[#This Row],[Task type]],'Forecast validation'!$A$14:$E$25,IF(tblWorkPackages[[#This Row],[Time split]]="Validation H1",4,5),FALSE())) | U5: =IF(tblWorkPackages[[#This Row],[Calibrated forecast hours]]="","",ABS(tblWorkPackages[[#This Row],[Actual labor hours]]-tblWorkPackages[[#This Row],[Calibrated forecast hours]])) | V5: =IF(tblWorkPackages[[#This Row],[Time split]]="Train 2024",tblWorkPackages[[#This Row],[Estimated labor hours]],tblWorkPackages[[#This Row],[Calibrated forecast hours]]) -> 9.4 | W5: =DATEVALUE(tblWorkPackages[[#This Row],[Request date]]) -> 45527 | X5: =DATEVALUE(tblWorkPackages[[#This Row],[Due date]]) -> 45529 | Y5: =DATEVALUE(tblWorkPackages[[#This Row],[Completion date]]) -> 45535 | Z5: =_xlfn.MINIFS(tblLaborEntries[Work date serial],tblLaborEntries[Work package ID],tblWorkPackages[[#This Row],[Work package ID]]) -> 45531 | AA5: =_xlfn.MAXIFS(tblLaborEntries[Work date serial],tblLaborEntries[Work package ID],tblWorkPackages[[#This Row],[Work package ID]]) -> 45532 | AB5: =IF(tblWorkPackages[[#This Row],[Completion date serial]]>tblWorkPackages[[#This Row],[Due date serial]],1,0) -> 1 | AC5: =MAX(0,tblWorkPackages[[#This Row],[Completion date serial]]-tblWorkPackages[[#This Row],[Due date serial]]) -> 6 | AD5: =tblWorkPackages[[#This Row],[First labor date]]-tblWorkPackages[[#This Row],[Request date serial]] -> 4 | AE5: =tblWorkPackages[[#This Row],[Last labor date]]-tblWorkPackages[[#This Row],[First labor date]] -> 1 | AF5: =tblWorkPackages[[#This Row],[Completion date serial]]-tblWorkPackages[[#This Row],[Last labor date]] -> 3 | AG5: =tblWorkPackages[[#This Row],[Completion date serial]]-tblWorkPackages[[#This Row],[Request date serial]] -> 8 | AH5: =IFERROR(INDEX(tblParts[Delay days],MATCH(tblWorkPackages[[#This Row],[Work package ID]],tblParts[Work package ID],0)),0) -> 0 | AI5: =IFERROR(INDEX(tblDisruptions[Event type],MATCH(tblWorkPackages[[#This Row],[Work package ID]],tblDisruptions[Work package ID],0)),"None") -> None | AJ5: =TEXT(tblWorkPackages[[#This Row],[Due date serial]],"yyyy-mm") -> 2024-08
A6: WP-00005 | B6: FT-05 | C6: 2024-12-01 | D6: 2024-12-14 | E6: Postflight discrepancy review | F6: Inspection | G6: Avionics | H6: 4 | I6: Routine | J6: 0 | K6: 1 | L6: 7.3 | M6: 2024-12-02 | N6: 8 | O6: =TEXT(tblWorkPackages[[#This Row],[Request date serial]]-WEEKDAY(tblWorkPackages[[#This Row],[Request date serial]],3),"yyyy-mm-dd") -> 2024-11-25 | P6: =ABS(tblWorkPackages[[#This Row],[Actual labor hours]]-tblWorkPackages[[#This Row],[Estimated labor hours]]) -> 0.7 | Q6: =IF(tblWorkPackages[[#This Row],[Actual labor hours]]>tblWorkPackages[[#This Row],[Estimated labor hours]],1,0) -> 1 | R6: =tblWorkPackages[[#This Row],[Actual labor hours]]-tblWorkPackages[[#This Row],[Estimated labor hours]] -> 0.7 | S6: =IF(tblWorkPackages[[#This Row],[Request date serial]]<ValidationStart,"Train 2024",IF(tblWorkPackages[[#This Row],[Request date serial]]<HoldoutStart,"Validation H1","Holdout H2")) -> Train 2024 | T6: =IF(tblWorkPackages[[#This Row],[Time split]]="Train 2024","",tblWorkPackages[[#This Row],[Estimated labor hours]]+VLOOKUP(tblWorkPackages[[#This Row],[Task type]],'Forecast validation'!$A$14:$E$25,IF(tblWorkPackages[[#This Row],[Time split]]="Validation H1",4,5),FALSE())) | U6: =IF(tblWorkPackages[[#This Row],[Calibrated forecast hours]]="","",ABS(tblWorkPackages[[#This Row],[Actual labor hours]]-tblWorkPackages[[#This Row],[Calibrated forecast hours]])) | V6: =IF(tblWorkPackages[[#This Row],[Time split]]="Train 2024",tblWorkPackages[[#This Row],[Estimated labor hours]],tblWorkPackages[[#This Row],[Calibrated forecast hours]]) -> 7.3 | W6: =DATEVALUE(tblWorkPackages[[#This Row],[Request date]]) -> 45627 | X6: =DATEVALUE(tblWorkPackages[[#This Row],[Due date]]) -> 45640 | Y6: =DATEVALUE(tblWorkPackages[[#This Row],[Completion date]]) -> 45628 | Z6: =_xlfn.MINIFS(tblLaborEntries[Work date serial],tblLaborEntries[Work package ID],tblWorkPackages[[#This Row],[Work package ID]]) -> 45628 | AA6: =_xlfn.MAXIFS(tblLaborEntries[Work date serial],tblLaborEntries[Work package ID],tblWorkPackages[[#This Row],[Work package ID]]) -> 45628 | AB6: =IF(tblWorkPackages[[#This Row],[Completion date serial]]>tblWorkPackages[[#This Row],[Due date serial]],1,0) -> 0 | AC6: =MAX(0,tblWorkPackages[[#This Row],[Completion date serial]]-tblWorkPackages[[#This Row],[Due date serial]]) -> 0 | AD6: =tblWorkPackages[[#This Row],[First labor date]]-tblWorkPackages[[#This Row],[Request date serial]] -> 1 | AE6: =tblWorkPackages[[#This Row],[Last labor date]]-tblWorkPackages[[#This Row],[First labor date]] -> 0 | AF6: =tblWorkPackages[[#This Row],[Completion date serial]]-tblWorkPackages[[#This Row],[Last labor date]] -> 0 | AG6: =tblWorkPackages[[#This Row],[Completion date serial]]-tblWorkPackages[[#This Row],[Request date serial]] -> 1 | AH6: =IFERROR(INDEX(tblParts[Delay days],MATCH(tblWorkPackages[[#This Row],[Work package ID]],tblParts[Work package ID],0)),0) -> 0 | AI6: =IFERROR(INDEX(tblDisruptions[Event type],MATCH(tblWorkPackages[[#This Row],[Work package ID]],tblDisruptions[Work package ID],0)),"None") -> None | AJ6: =TEXT(tblWorkPackages[[#This Row],[Due date serial]],"yyyy-mm") -> 2024-12
A7: WP-00006 | B7: FT-11 | C7: 2024-06-29 | D7: 2024-07-01 | E7: Flight control inspection | F7: Inspection | G7: Airframe | H7: 2 | I7: Urgent | J7: 0 | K7: 1 | L7: 7.2 | M7: 2024-07-12 | N7: 7.2 | O7: =TEXT(tblWorkPackages[[#This Row],[Request date serial]]-WEEKDAY(tblWorkPackages[[#This Row],[Request date serial]],3),"yyyy-mm-dd") -> 2024-06-24 | P7: =ABS(tblWorkPackages[[#This Row],[Actual labor hours]]-tblWorkPackages[[#This Row],[Estimated labor hours]]) -> 0 | Q7: =IF(tblWorkPackages[[#This Row],[Actual labor hours]]>tblWorkPackages[[#This Row],[Estimated labor hours]],1,0) -> 0 | R7: =tblWorkPackages[[#This Row],[Actual labor hours]]-tblWorkPackages[[#This Row],[Estimated labor hours]] -> 0 | S7: =IF(tblWorkPackages[[#This Row],[Request date serial]]<ValidationStart,"Train 2024",IF(tblWorkPackages[[#This Row],[Request date serial]]<HoldoutStart,"Validation H1","Holdout H2")) -> Train 2024 | T7: =IF(tblWorkPackages[[#This Row],[Time split]]="Train 2024","",tblWorkPackages[[#This Row],[Estimated labor hours]]+VLOOKUP(tblWorkPackages[[#This Row],[Task type]],'Forecast validation'!$A$14:$E$25,IF(tblWorkPackages[[#This Row],[Time split]]="Validation H1",4,5),FALSE())) | U7: =IF(tblWorkPackages[[#This Row],[Calibrated forecast hours]]="","",ABS(tblWorkPackages[[#This Row],[Actual labor hours]]-tblWorkPackages[[#This Row],[Calibrated forecast hours]])) | V7: =IF(tblWorkPackages[[#This Row],[Time split]]="Train 2024",tblWorkPackages[[#This Row],[Estimated labor hours]],tblWorkPackages[[#This Row],[Calibrated forecast hours]]) -> 7.2 | W7: =DATEVALUE(tblWorkPackages[[#This Row],[Request date]]) -> 45472 | X7: =DATEVALUE(tblWorkPackages[[#This Row],[Due date]]) -> 45474 | Y7: =DATEVALUE(tblWorkPackages[[#This Row],[Completion date]]) -> 45485 | Z7: =_xlfn.MINIFS(tblLaborEntries[Work date serial],tblLaborEntries[Work package ID],tblWorkPackages[[#This Row],[Work package ID]]) -> 45484 | AA7: =_xlfn.MAXIFS(tblLaborEntries[Work date serial],tblLaborEntries[Work package ID],tblWorkPackages[[#This Row],[Work package ID]]) -> 45484 | AB7: =IF(tblWorkPackages[[#This Row],[Completion date serial]]>tblWorkPackages[[#This Row],[Due date serial]],1,0) -> 1 | AC7: =MAX(0,tblWorkPackages[[#This Row],[Completion date serial]]-tblWorkPackages[[#This Row],[Due date serial]]) -> 11 | AD7: =tblWorkPackages[[#This Row],[First labor date]]-tblWorkPackages[[#This Row],[Request date serial]] -> 12 | AE7: =tblWorkPackages[[#This Row],[Last labor date]]-tblWorkPackages[[#This Row],[First labor date]] -> 0 | AF7: =tblWorkPackages[[#This Row],[Completion date serial]]-tblWorkPackages[[#This Row],[Last labor date]] -> 1 | AG7: =tblWorkPackages[[#This Row],[Completion date serial]]-tblWorkPackages[[#This Row],[Request date serial]] -> 13 | AH7: =IFERROR(INDEX(tblParts[Delay days],MATCH(tblWorkPackages[[#This Row],[Work package ID]],tblParts[Work package ID],0)),0) -> 0 | AI7: =IFERROR(INDEX(tblDisruptions[Event type],MATCH(tblWorkPackages[[#This Row],[Work package ID]],tblDisruptions[Work package ID],0)),"None") -> None | AJ7: =TEXT(tblWorkPackages[[#This Row],[Due date serial]],"yyyy-mm") -> 2024-07
A8: WP-00007 | B8: FT-08 | C8: 2024-10-20 | D8: 2024-10-22 | E8: Flight control inspection | F8: Inspection | G8: Airframe | H8: 1 | I8: Urgent | J8: 0 | K8: 0 | L8: 4.2 | M8: 2024-10-25 | N8: 4.9 | O8: =TEXT(tblWorkPackages[[#This Row],[Request date serial]]-WEEKDAY(tblWorkPackages[[#This Row],[Request date serial]],3),"yyyy-mm-dd") -> 2024-10-14 | P8: =ABS(tblWorkPackages[[#This Row],[Actual labor hours]]-tblWorkPackages[[#This Row],[Estimated labor hours]]) -> 0.7 | Q8: =IF(tblWorkPackages[[#This Row],[Actual labor hours]]>tblWorkPackages[[#This Row],[Estimated labor hours]],1,0) -> 1 | R8: =tblWorkPackages[[#This Row],[Actual labor hours]]-tblWorkPackages[[#This Row],[Estimated labor hours]] -> 0.7 | S8: =IF(tblWorkPackages[[#This Row],[Request date serial]]<ValidationStart,"Train 2024",IF(tblWorkPackages[[#This Row],[Request date serial]]<HoldoutStart,"Validation H1","Holdout H2")) -> Train 2024 | T8: =IF(tblWorkPackages[[#This Row],[Time split]]="Train 2024","",tblWorkPackages[[#This Row],[Estimated labor hours]]+VLOOKUP(tblWorkPackages[[#This Row],[Task type]],'Forecast validation'!$A$14:$E$25,IF(tblWorkPackages[[#This Row],[Time split]]="Validation H1",4,5),FALSE())) | U8: =IF(tblWorkPackages[[#This Row],[Calibrated forecast hours]]="","",ABS(tblWorkPackages[[#This Row],[Actual labor hours]]-tblWorkPackages[[#This Row],[Calibrated forecast hours]])) | V8: =IF(tblWorkPackages[[#This Row],[Time split]]="Train 2024",tblWorkPackages[[#This Row],[Estimated labor hours]],tblWorkPackages[[#This Row],[Calibrated forecast hours]]) -> 4.2 | W8: =DATEVALUE(tblWorkPackages[[#This Row],[Request date]]) -> 45585 | X8: =DATEVALUE(tblWorkPackages[[#This Row],[Due date]]) -> 45587 | Y8: =DATEVALUE(tblWorkPackages[[#This Row],[Completion date]]) -> 45590 | Z8: =_xlfn.MINIFS(tblLaborEntries[Work date serial],tblLaborEntries[Work package ID],tblWorkPackages[[#This Row],[Work package ID]]) -> 45588 | AA8: =_xlfn.MAXIFS(tblLaborEntries[Work date serial],tblLaborEntries[Work package ID],tblWorkPackages[[#This Row],[Work package ID]]) -> 45588 | AB8: =IF(tblWorkPackages[[#This Row],[Completion date serial]]>tblWorkPackages[[#This Row],[Due date serial]],1,0) -> 1 | AC8: =MAX(0,tblWorkPackages[[#This Row],[Completion date serial]]-tblWorkPackages[[#This Row],[Due date serial]]) -> 3 | AD8: =tblWorkPackages[[#This Row],[First labor date]]-tblWorkPackages[[#This Row],[Request date serial]] -> 3 | AE8: =tblWorkPackages[[#This Row],[Last labor date]]-tblWorkPackages[[#This Row],[First labor date]] -> 0 | AF8: =tblWorkPackages[[#This Row],[Completion date serial]]-tblWorkPackages[[#This Row],[Last labor date]] -> 2 | AG8: =tblWorkPackages[[#This Row],[Completion date serial]]-tblWorkPackages[[#This Row],[Request date serial]] -> 5 | AH8: =IFERROR(INDEX(tblParts[Delay days],MATCH(tblWorkPackages[[#This Row],[Work package ID]],tblParts[Work package ID],0)),0) -> 0 | AI8: =IFERROR(INDEX(tblDisruptions[Event type],MATCH(tblWorkPackages[[#This Row],[Work package ID]],tblDisruptions[Work package ID],0)),"None") -> None | AJ8: =TEXT(tblWorkPackages[[#This Row],[Due date serial]],"yyyy-mm") -> 2024-10
A9: WP-00008 | B9: FT-01 | C9: 2025-06-28 | D9: 2025-07-04 | E9: Hydraulic leak diagnosis | F9: Corrective | G9: Hydraulics | H9: 1 | I9: High | J9: 0 | K9: 1 | L9: 7 | M9: 2025-08-17 | N9: 11 | O9: =TEXT(tblWorkPackages[[#This Row],[Request date serial]]-WEEKDAY(tblWorkPackages[[#This Row],[Request date serial]],3),"yyyy-mm-dd") -> 2025-06-23 | P9: =ABS(tblWorkPackages[[#This Row],[Actual labor hours]]-tblWorkPackages[[#This Row],[Estimated labor hours]]) -> 4 | Q9: =IF(tblWorkPackages[[#This Row],[Actual labor hours]]>tblWorkPackages[[#This Row],[Estimated labor hours]],1,0) -> 1 | R9: =tblWorkPackages[[#This Row],[Actual labor hours]]-tblWorkPackages[[#This Row],[Estimated labor hours]] -> 4 | S9: =IF(tblWorkPackages[[#This Row],[Request date serial]]<ValidationStart,"Train 2024",IF(tblWorkPackages[[#This Row],[Request date serial]]<HoldoutStart,"Validation H1","Holdout H2")) -> Validation H1 | T9: =IF(tblWorkPackages[[#This Row],[Time split]]="Train 2024","",tblWorkPackages[[#This Row],[Estimated labor hours]]+VLOOKUP(tblWorkPackages[[#This Row],[Task type]],'Forecast validation'!$A$14:$E$25,IF(tblWorkPackages[[#This Row],[Time split]]="Validation H1",4,5),FALSE())) -> 7.7547368 | U9: =IF(tblWorkPackages[[#This Row],[Calibrated forecast hours]]="","",ABS(tblWorkPackages[[#This Row],[Actual labor hours]]-tblWorkPackages[[#This Row],[Calibrated forecast hours]])) -> 3.2452632 | V9: =IF(tblWorkPackages[[#This Row],[Time split]]="Train 2024",tblWorkPackages[[#This Row],[Estimated labor hours]],tblWorkPackages[[#This Row],[Calibrated forecast hours]]) -> 7.7547368 | W9: =DATEVALUE(tblWorkPackages[[#This Row],[Request date]]) -> 45836 | X9: =DATEVALUE(tblWorkPackages[[#This Row],[Due date]]) -> 45842 | Y9: =DATEVALUE(tblWorkPackages[[#This Row],[Completion date]]) -> 45886 | Z9: =_xlfn.MINIFS(tblLaborEntries[Work date serial],tblLaborEntries[Work package ID],tblWorkPackages[[#This Row],[Work package ID]]) -> 45882 | AA9: =_xlfn.MAXIFS(tblLaborEntries[Work date serial],tblLaborEntries[Work package ID],tblWorkPackages[[#This Row],[Work package ID]]) -> 45883 | AB9: =IF(tblWorkPackages[[#This Row],[Completion date serial]]>tblWorkPackages[[#This Row],[Due date serial]],1,0) -> 1 | AC9: =MAX(0,tblWorkPackages[[#This Row],[Completion date serial]]-tblWorkPackages[[#This Row],[Due date serial]]) -> 44 | AD9: =tblWorkPackages[[#This Row],[First labor date]]-tblWorkPackages[[#This Row],[Request date serial]] -> 46 | AE9: =tblWorkPackages[[#This Row],[Last labor date]]-tblWorkPackages[[#This Row],[First labor date]] -> 1 | AF9: =tblWorkPackages[[#This Row],[Completion date serial]]-tblWorkPackages[[#This Row],[Last labor date]] -> 3 | AG9: =tblWorkPackages[[#This Row],[Completion date serial]]-tblWorkPackages[[#This Row],[Request date serial]] -> 50 | AH9: =IFERROR(INDEX(tblParts[Delay days],MATCH(tblWorkPackages[[#This Row],[Work package ID]],tblParts[Work package ID],0)),0) -> 10 | AI9: =IFERROR(INDEX(tblDisruptions[Event type],MATCH(tblWorkPackages[[#This Row],[Work package ID]],tblDisruptions[Work package ID],0)),"None") -> Part delay | AJ9: =TEXT(tblWorkPackages[[#This Row],[Due date serial]],"yyyy-mm") -> 2025-07
A10: WP-00009 | B10: FT-03 | C10: 2025-05-15 | D10: 2025-05-28 | E10: Sensor calibration | F10: Test support | G10: Avionics | H10: 2 | I10: Routine | J10: 0 | K10: 1 | L10: 8.6 | M10: 2025-05-22 | N10: 8.2 | O10: =TEXT(tblWorkPackages[[#This Row],[Request date serial]]-WEEKDAY(tblWorkPackages[[#This Row],[Request date serial]],3),"yyyy-mm-dd") -> 2025-05-12 | P10: =ABS(tblWorkPackages[[#This Row],[Actual labor hours]]-tblWorkPackages[[#This Row],[Estimated labor hours]]) -> 0.4 | Q10: =IF(tblWorkPackages[[#This Row],[Actual labor hours]]>tblWorkPackages[[#This Row],[Estimated labor hours]],1,0) -> 0 | R10: =tblWorkPackages[[#This Row],[Actual labor hours]]-tblWorkPackages[[#This Row],[Estimated labor hours]] -> -0.4 | S10: =IF(tblWorkPackages[[#This Row],[Request date serial]]<ValidationStart,"Train 2024",IF(tblWorkPackages[[#This Row],[Request date serial]]<HoldoutStart,"Validation H1","Holdout H2")) -> Validation H1 | T10: =IF(tblWorkPackages[[#This Row],[Time split]]="Train 2024","",tblWorkPackages[[#This Row],[Estimated labor hours]]+VLOOKUP(tblWorkPackages[[#This Row],[Task type]],'Forecast validation'!$A$14:$E$25,IF(tblWorkPackages[[#This Row],[Time split]]="Validation H1",4,5),FALSE())) -> 9.1840909 | U10: =IF(tblWorkPackages[[#This Row],[Calibrated forecast hours]]="","",ABS(tblWorkPackages[[#This Row],[Actual labor hours]]-tblWorkPackages[[#This Row],[Calibrated forecast hours]])) -> 0.98409091 | V10: =IF(tblWorkPackages[[#This Row],[Time split]]="Train 2024",tblWorkPackages[[#This Row],[Estimated labor hours]],tblWorkPackages[[#This Row],[Calibrated forecast hours]]) -> 9.1840909 | W10: =DATEVALUE(tblWorkPackages[[#This Row],[Request date]]) -> 45792 | X10: =DATEVALUE(tblWorkPackages[[#This Row],[Due date]]) -> 45805 | Y10: =DATEVALUE(tblWorkPackages[[#This Row],[Completion date]]) -> 45799 | Z10: =_xlfn.MINIFS(tblLaborEntries[Work date serial],tblLaborEntries[Work package ID],tblWorkPackages[[#This Row],[Work package ID]]) -> 45799 | AA10: =_xlfn.MAXIFS(tblLaborEntries[Work date serial],tblLaborEntries[Work package ID],tblWorkPackages[[#This Row],[Work package ID]]) -> 45799 | AB10: =IF(tblWorkPackages[[#This Row],[Completion date serial]]>tblWorkPackages[[#This Row],[Due date serial]],1,0) -> 0 | AC10: =MAX(0,tblWorkPackages[[#This Row],[Completion date serial]]-tblWorkPackages[[#This Row],[Due date serial]]) -> 0 | AD10: =tblWorkPackages[[#This Row],[First labor date]]-tblWorkPackages[[#This Row],[Request date serial]] -> 7 | AE10: =tblWorkPackages[[#This Row],[Last labor date]]-tblWorkPackages[[#This Row],[First labor date]] -> 0 | AF10: =tblWorkPackages[[#This Row],[Completion date serial]]-tblWorkPackages[[#This Row],[Last labor date]] -> 0 | AG10: =tblWorkPackages[[#This Row],[Completion date serial]]-tblWorkPackages[[#This Row],[Request date serial]] -> 7 | AH10: =IFERROR(INDEX(tblParts[Delay days],MATCH(tblWorkPackages[[#This Row],[Work package ID]],tblParts[Work package ID],0)),0) -> 0 | AI10: =IFERROR(INDEX(tblDisruptions[Event type],MATCH(tblWorkPackages[[#This Row],[Work package ID]],tblDisruptions[Work package ID],0)),"None") -> None | AJ10: =TEXT(tblWorkPackages[[#This Row],[Due date serial]],"yyyy-mm") -> 2025-05
A11: WP-00010 | B11: FT-09 | C11: 2025-02-19 | D11: 2025-02-25 | E11: Instrumentation installation | F11: Modification | G11: Avionics | H11: 1 | I11: High | J11: 0 | K11: 0 | L11: 10.5 | M11: 2025-02-23 | N11: 9 | O11: =TEXT(tblWorkPackages[[#This Row],[Request date serial]]-WEEKDAY(tblWorkPackages[[#This Row],[Request date serial]],3),"yyyy-mm-dd") -> 2025-02-17 | P11: =ABS(tblWorkPackages[[#This Row],[Actual labor hours]]-tblWorkPackages[[#This Row],[Estimated labor hours]]) -> 1.5 | Q11: =IF(tblWorkPackages[[#This Row],[Actual labor hours]]>tblWorkPackages[[#This Row],[Estimated labor hours]],1,0) -> 0 | R11: =tblWorkPackages[[#This Row],[Actual labor hours]]-tblWorkPackages[[#This Row],[Estimated labor hours]] -> -1.5 | S11: =IF(tblWorkPackages[[#This Row],[Request date serial]]<ValidationStart,"Train 2024",IF(tblWorkPackages[[#This Row],[Request date serial]]<HoldoutStart,"Validation H1","Holdout H2")) -> Validation H1 | T11: =IF(tblWorkPackages[[#This Row],[Time split]]="Train 2024","",tblWorkPackages[[#This Row],[Estimated labor hours]]+VLOOKUP(tblWorkPackages[[#This Row],[Task type]],'Forecast validation'!$A$14:$E$25,IF(tblWorkPackages[[#This Row],[Time split]]="Validation H1",4,5),FALSE())) -> 11.376531 | U11: =IF(tblWorkPackages[[#This Row],[Calibrated forecast hours]]="","",ABS(tblWorkPackages[[#This Row],[Actual labor hours]]-tblWorkPackages[[#This Row],[Calibrated forecast hours]])) -> 2.3765306 | V11: =IF(tblWorkPackages[[#This Row],[Time split]]="Train 2024",tblWorkPackages[[#This Row],[Estimated labor hours]],tblWorkPackages[[#This Row],[Calibrated forecast hours]]) -> 11.376531 | W11: =DATEVALUE(tblWorkPackages[[#This Row],[Request date]]) -> 45707 | X11: =DATEVALUE(tblWorkPackages[[#This Row],[Due date]]) -> 45713 | Y11: =DATEVALUE(tblWorkPackages[[#This Row],[Completion date]]) -> 45711 | Z11: =_xlfn.MINIFS(tblLaborEntries[Work date serial],tblLaborEntries[Work package ID],tblWorkPackages[[#This Row],[Work package ID]]) -> 45709 | AA11: =_xlfn.MAXIFS(tblLaborEntries[Work date serial],tblLaborEntries[Work package ID],tblWorkPackages[[#This Row],[Work package ID]]) -> 45710 | AB11: =IF(tblWorkPackages[[#This Row],[Completion date serial]]>tblWorkPackages[[#This Row],[Due date serial]],1,0) -> 0 | AC11: =MAX(0,tblWorkPackages[[#This Row],[Completion date serial]]-tblWorkPackages[[#This Row],[Due date serial]]) -> 0 | AD11: =tblWorkPackages[[#This Row],[First labor date]]-tblWorkPackages[[#This Row],[Request date serial]] -> 2 | AE11: =tblWorkPackages[[#This Row],[Last labor date]]-tblWorkPackages[[#This Row],[First labor date]] -> 1 | AF11: =tblWorkPackages[[#This Row],[Completion date serial]]-tblWorkPackages[[#This Row],[Last labor date]] -> 1 | AG11: =tblWorkPackages[[#This Row],[Completion date serial]]-tblWorkPackages[[#This Row],[Request date serial]] -> 4 | AH11: =IFERROR(INDEX(tblParts[Delay days],MATCH(tblWorkPackages[[#This Row],[Work package ID]],tblParts[Work package ID],0)),0) -> 0 | AI11: =IFERROR(INDEX(tblDisruptions[Event type],MATCH(tblWorkPackages[[#This Row],[Work package ID]],tblDisruptions[Work package ID],0)),"None") -> None | AJ11: =TEXT(tblWorkPackages[[#This Row],[Due date serial]],"yyyy-mm") -> 2025-02
A12: WP-00011 | B12: FT-06 | C12: 2025-08-14 | D12: 2025-08-27 | E12: Sensor calibration | F12: Test support | G12: Avionics | H12: 2 | I12: Routine | J12: 0 | K12: 0 | L12: 6.8 | M12: 2025-08-31 | N12: 5.2 | O12: =TEXT(tblWorkPackages[[#This Row],[Request date serial]]-WEEKDAY(tblWorkPackages[[#This Row],[Request date serial]],3),"yyyy-mm-dd") -> 2025-08-11 | P12: =ABS(tblWorkPackages[[#This Row],[Actual labor hours]]-tblWorkPackages[[#This Row],[Estimated labor hours]]) -> 1.6 | Q12: =IF(tblWorkPackages[[#This Row],[Actual labor hours]]>tblWorkPackages[[#This Row],[Estimated labor hours]],1,0) -> 0 | R12: =tblWorkPackages[[#This Row],[Actual labor hours]]-tblWorkPackages[[#This Row],[Estimated labor hours]] -> -1.6 | S12: =IF(tblWorkPackages[[#This Row],[Request date serial]]<ValidationStart,"Train 2024",IF(tblWorkPackages[[#This Row],[Request date serial]]<HoldoutStart,"Validation H1","Holdout H2")) -> Holdout H2 | T12: =IF(tblWorkPackages[[#This Row],[Time split]]="Train 2024","",tblWorkPackages[[#This Row],[Estimated labor hours]]+VLOOKUP(tblWorkPackages[[#This Row],[Task type]],'Forecast validation'!$A$14:$E$25,IF(tblWorkPackages[[#This Row],[Time split]]="Validation H1",4,5),FALSE())) -> 7.3916084 | U12: =IF(tblWorkPackages[[#This Row],[Calibrated forecast hours]]="","",ABS(tblWorkPackages[[#This Row],[Actual labor hours]]-tblWorkPackages[[#This Row],[Calibrated forecast hours]])) -> 2.1916084 | V12: =IF(tblWorkPackages[[#This Row],[Time split]]="Train 2024",tblWorkPackages[[#This Row],[Estimated labor hours]],tblWorkPackages[[#This Row],[Calibrated forecast hours]]) -> 7.3916084 | W12: =DATEVALUE(tblWorkPackages[[#This Row],[Request date]]) -> 45883 | X12: =DATEVALUE(tblWorkPackages[[#This Row],[Due date]]) -> 45896 | Y12: =DATEVALUE(tblWorkPackages[[#This Row],[Completion date]]) -> 45900 | Z12: =_xlfn.MINIFS(tblLaborEntries[Work date serial],tblLaborEntries[Work package ID],tblWorkPackages[[#This Row],[Work package ID]]) -> 45898 | AA12: =_xlfn.MAXIFS(tblLaborEntries[Work date serial],tblLaborEntries[Work package ID],tblWorkPackages[[#This Row],[Work package ID]]) -> 45898 | AB12: =IF(tblWorkPackages[[#This Row],[Completion date serial]]>tblWorkPackages[[#This Row],[Due date serial]],1,0) -> 1 | AC12: =MAX(0,tblWorkPackages[[#This Row],[Completion date serial]]-tblWorkPackages[[#This Row],[Due date serial]]) -> 4 | AD12: =tblWorkPackages[[#This Row],[First labor date]]-tblWorkPackages[[#This Row],[Request date serial]] -> 15 | AE12: =tblWorkPackages[[#This Row],[Last labor date]]-tblWorkPackages[[#This Row],[First labor date]] -> 0 | AF12: =tblWorkPackages[[#This Row],[Completion date serial]]-tblWorkPackages[[#This Row],[Last labor date]] -> 2 | AG12: =tblWorkPackages[[#This Row],[Completion date serial]]-tblWorkPackages[[#This Row],[Request date serial]] -> 17 | AH12: =IFERROR(INDEX(tblParts[Delay days],MATCH(tblWorkPackages[[#This Row],[Work package ID]],tblParts[Work package ID],0)),0) -> 0 | AI12: =IFERROR(INDEX(tblDisruptions[Event type],MATCH(tblWorkPackages[[#This Row],[Work package ID]],tblDisruptions[Work package ID],0)),"None") -> None | AJ12: =TEXT(tblWorkPackages[[#This Row],[Due date serial]],"yyyy-mm") -> 2025-08
A13: WP-00012 | B13: FT-08 | C13: 2024-10-09 | D13: 2024-10-15 | E13: Sensor calibration | F13: Test support | G13: Avionics | H13: 1 | I13: High | J13: 0 | K13: 0 | L13: 4.5 | M13: 2024-10-17 | N13: 5.7 | O13: =TEXT(tblWorkPackages[[#This Row],[Request date serial]]-WEEKDAY(tblWorkPackages[[#This Row],[Request date serial]],3),"yyyy-mm-dd") -> 2024-10-07 | P13: =ABS(tblWorkPackages[[#This Row],[Actual labor hours]]-tblWorkPackages[[#This Row],[Estimated labor hours]]) -> 1.2 | Q13: =IF(tblWorkPackages[[#This Row],[Actual labor hours]]>tblWorkPackages[[#This Row],[Estimated labor hours]],1,0) -> 1 | R13: =tblWorkPackages[[#This Row],[Actual labor hours]]-tblWorkPackages[[#This Row],[Estimated labor hours]] -> 1.2 | S13: =IF(tblWorkPackages[[#This Row],[Request date serial]]<ValidationStart,"Train 2024",IF(tblWorkPackages[[#This Row],[Request date serial]]<HoldoutStart,"Validation H1","Holdout H2")) -> Train 2024 | T13: =IF(tblWorkPackages[[#This Row],[Time split]]="Train 2024","",tblWorkPackages[[#This Row],[Estimated labor hours]]+VLOOKUP(tblWorkPackages[[#This Row],[Task type]],'Forecast validation'!$A$14:$E$25,IF(tblWorkPackages[[#This Row],[Time split]]="Validation H1",4,5),FALSE())) | U13: =IF(tblWorkPackages[[#This Row],[Calibrated forecast hours]]="","",ABS(tblWorkPackages[[#This Row],[Actual labor hours]]-tblWorkPackages[[#This Row],[Calibrated forecast hours]])) | V13: =IF(tblWorkPackages[[#This Row],[Time split]]="Train 2024",tblWorkPackages[[#This Row],[Estimated labor hours]],tblWorkPackages[[#This Row],[Calibrated forecast hours]]) -> 4.5 | W13: =DATEVALUE(tblWorkPackages[[#This Row],[Request date]]) -> 45574 | X13: =DATEVALUE(tblWorkPackages[[#This Row],[Due date]]) -> 45580 | Y13: =DATEVALUE(tblWorkPackages[[#This Row],[Completion date]]) -> 45582 | Z13: =_xlfn.MINIFS(tblLaborEntries[Work date serial],tblLaborEntries[Work package ID],tblWorkPackages[[#This Row],[Work package ID]]) -> 45578 | AA13: =_xlfn.MAXIFS(tblLaborEntries[Work date serial],tblLaborEntries[Work package ID],tblWorkPackages[[#This Row],[Work package ID]]) -> 45579 | AB13: =IF(tblWorkPackages[[#This Row],[Completion date serial]]>tblWorkPackages[[#This Row],[Due date serial]],1,0) -> 1 | AC13: =MAX(0,tblWorkPackages[[#This Row],[Completion date serial]]-tblWorkPackages[[#This Row],[Due date serial]]) -> 2 | AD13: =tblWorkPackages[[#This Row],[First labor date]]-tblWorkPackages[[#This Row],[Request date serial]] -> 4 | AE13: =tblWorkPackages[[#This Row],[Last labor date]]-tblWorkPackages[[#This Row],[First labor date]] -> 1 | AF13: =tblWorkPackages[[#This Row],[Completion date serial]]-tblWorkPackages[[#This Row],[Last labor date]] -> 3 | AG13: =tblWorkPackages[[#This Row],[Completion date serial]]-tblWorkPackages[[#This Row],[Request date serial]] -> 8 | AH13: =IFERROR(INDEX(tblParts[Delay days],MATCH(tblWorkPackages[[#This Row],[Work package ID]],tblParts[Work package ID],0)),0) -> 0 | AI13: =IFERROR(INDEX(tblDisruptions[Event type],MATCH(tblWorkPackages[[#This Row],[Work package ID]],tblDisruptions[Work package ID],0)),"None") -> None | AJ13: =TEXT(tblWorkPackages[[#This Row],[Due date serial]],"yyyy-mm") -> 2024-10
... A2401: WP-02400 | B2401: FT-03 | C2401: 2024-08-10 | D2401: 2024-08-16 | E2401: Preflight inspection | F2401: Inspection | G2401: Airframe | H2401: 3 | I2401: High | J2401: 0 | K2401: 0 | L2401: 4 | M2401: 2024-08-17 | N2401: 4 | O2401: =TEXT(tblWorkPackages[[#This Row],[Request date serial]]-WEEKDAY(tblWorkPackages[[#This Row],[Request date serial]],3),"yyyy-mm-dd") -> 2024-08-05 | P2401: =ABS(tblWorkPackages[[#This Row],[Actual labor hours]]-tblWorkPackages[[#This Row],[Estimated labor hours]]) -> 0 | Q2401: =IF(tblWorkPackages[[#This Row],[Actual labor hours]]>tblWorkPackages[[#This Row],[Estimated labor hours]],1,0) -> 0 | R2401: =tblWorkPackages[[#This Row],[Actual labor hours]]-tblWorkPackages[[#This Row],[Estimated labor hours]] -> 0 | S2401: =IF(tblWorkPackages[[#This Row],[Request date serial]]<ValidationStart,"Train 2024",IF(tblWorkPackages[[#This Row],[Request date serial]]<HoldoutStart,"Validation H1","Holdout H2")) -> Train 2024 | T2401: =IF(tblWorkPackages[[#This Row],[Time split]]="Train 2024","",tblWorkPackages[[#This Row],[Estimated labor hours]]+VLOOKUP(tblWorkPackages[[#This Row],[Task type]],'Forecast validation'!$A$14:$E$25,IF(tblWorkPackages[[#This Row],[Time split]]="Validation H1",4,5),FALSE())) | U2401: =IF(tblWorkPackages[[#This Row],[Calibrated forecast hours]]="","",ABS(tblWorkPackages[[#This Row],[Actual labor hours]]-tblWorkPackages[[#This Row],[Calibrated forecast hours]])) | V2401: =IF(tblWorkPackages[[#This Row],[Time split]]="Train 2024",tblWorkPackages[[#This Row],[Estimated labor hours]],tblWorkPackages[[#This Row],[Calibrated forecast hours]]) -> 4 | W2401: =DATEVALUE(tblWorkPackages[[#This Row],[Request date]]) -> 45514 | X2401: =DATEVALUE(tblWorkPackages[[#This Row],[Due date]]) -> 45520 | Y2401: =DATEVALUE(tblWorkPackages[[#This Row],[Completion date]]) -> 45521 | Z2401: =_xlfn.MINIFS(tblLaborEntries[Work date serial],tblLaborEntries[Work package ID],tblWorkPackages[[#This Row],[Work package ID]]) -> 45517 | AA2401: =_xlfn.MAXIFS(tblLaborEntries[Work date serial],tblLaborEntries[Work package ID],tblWorkPackages[[#This Row],[Work package ID]]) -> 45518 | AB2401: =IF(tblWorkPackages[[#This Row],[Completion date serial]]>tblWorkPackages[[#This Row],[Due date serial]],1,0) -> 1 | AC2401: =MAX(0,tblWorkPackages[[#This Row],[Completion date serial]]-tblWorkPackages[[#This Row],[Due date serial]]) -> 1 | AD2401: =tblWorkPackages[[#This Row],[First labor date]]-tblWorkPackages[[#This Row],[Request date serial]] -> 3 | AE2401: =tblWorkPackages[[#This Row],[Last labor date]]-tblWorkPackages[[#This Row],[First labor date]] -> 1 | AF2401: =tblWorkPackages[[#This Row],[Completion date serial]]-tblWorkPackages[[#This Row],[Last labor date]] -> 3 | AG2401: =tblWorkPackages[[#This Row],[Completion date serial]]-tblWorkPackages[[#This Row],[Request date serial]] -> 7 | AH2401: =IFERROR(INDEX(tblParts[Delay days],MATCH(tblWorkPackages[[#This Row],[Work package ID]],tblParts[Work package ID],0)),0) -> 0 | AI2401: =IFERROR(INDEX(tblDisruptions[Event type],MATCH(tblWorkPackages[[#This Row],[Work package ID]],tblDisruptions[Work package ID],0)),"None") -> None | AJ2401: =TEXT(tblWorkPackages[[#This Row],[Due date serial]],"yyyy-mm") -> 2024-08

Sheet Labor entries
A1: Labor entry ID | B1: Work package ID | C1: Technician ID | D1: Skill booked | E1: Work date | F1: Hours booked | G1: Overtime hours | H1: Work week (Monday) | I1: Work date serial
A2: LAB-000001 | B2: WP-00001 | C2: TECH-007 | D2: Airframe | E2: 2025-05-12 | F2: 3.8 | G2: 0 | H2: =TEXT(tblLaborEntries[[#This Row],[Work date serial]]-WEEKDAY(tblLaborEntries[[#This Row],[Work date serial]],3),"yyyy-mm-dd") -> 2025-05-12 | I2: =DATEVALUE(tblLaborEntries[[#This Row],[Work date]]) -> 45789
A3: LAB-000002 | B3: WP-00001 | C3: TECH-055 | D3: Airframe | E3: 2025-05-13 | F3: 4 | G3: 0 | H3: =TEXT(tblLaborEntries[[#This Row],[Work date serial]]-WEEKDAY(tblLaborEntries[[#This Row],[Work date serial]],3),"yyyy-mm-dd") -> 2025-05-12 | I3: =DATEVALUE(tblLaborEntries[[#This Row],[Work date]]) -> 45790
A4: LAB-000003 | B4: WP-00001 | C4: TECH-055 | D4: Airframe | E4: 2025-05-14 | F4: 3 | G4: 0 | H4: =TEXT(tblLaborEntries[[#This Row],[Work date serial]]-WEEKDAY(tblLaborEntries[[#This Row],[Work date serial]],3),"yyyy-mm-dd") -> 2025-05-12 | I4: =DATEVALUE(tblLaborEntries[[#This Row],[Work date]]) -> 45791
A5: LAB-000004 | B5: WP-00002 | C5: TECH-038 | D5: Avionics | E5: 2025-09-07 | F5: 6.9 | G5: 0 | H5: =TEXT(tblLaborEntries[[#This Row],[Work date serial]]-WEEKDAY(tblLaborEntries[[#This Row],[Work date serial]],3),"yyyy-mm-dd") -> 2025-09-01 | I5: =DATEVALUE(tblLaborEntries[[#This Row],[Work date]]) -> 45907
A6: LAB-000005 | B6: WP-00003 | C6: TECH-033 | D6: Hydraulics | E6: 2024-02-23 | F6: 7.9 | G6: 0 | H6: =TEXT(tblLaborEntries[[#This Row],[Work date serial]]-WEEKDAY(tblLaborEntries[[#This Row],[Work date serial]],3),"yyyy-mm-dd") -> 2024-02-19 | I6: =DATEVALUE(tblLaborEntries[[#This Row],[Work date]]) -> 45345
A7: LAB-000006 | B7: WP-00003 | C7: TECH-063 | D7: Hydraulics | E7: 2024-02-24 | F7: 6.8 | G7: 0 | H7: =TEXT(tblLaborEntries[[#This Row],[Work date serial]]-WEEKDAY(tblLaborEntries[[#This Row],[Work date serial]],3),"yyyy-mm-dd") -> 2024-02-19 | I7: =DATEVALUE(tblLaborEntries[[#This Row],[Work date]]) -> 45346
A8: LAB-000007 | B8: WP-00004 | C8: TECH-030 | D8: Powerplant | E8: 2024-08-27 | F8: 6.2 | G8: 0 | H8: =TEXT(tblLaborEntries[[#This Row],[Work date serial]]-WEEKDAY(tblLaborEntries[[#This Row],[Work date serial]],3),"yyyy-mm-dd") -> 2024-08-26 | I8: =DATEVALUE(tblLaborEntries[[#This Row],[Work date]]) -> 45531
A9: LAB-000008 | B9: WP-00004 | C9: TECH-054 | D9: Powerplant | E9: 2024-08-28 | F9: 6.7 | G9: 0 | H9: =TEXT(tblLaborEntries[[#This Row],[Work date serial]]-WEEKDAY(tblLaborEntries[[#This Row],[Work date serial]],3),"yyyy-mm-dd") -> 2024-08-26 | I9: =DATEVALUE(tblLaborEntries[[#This Row],[Work date]]) -> 45532
A10: LAB-000009 | B10: WP-00005 | C10: TECH-002 | D10: Avionics | E10: 2024-12-02 | F10: 8 | G10: 0 | H10: =TEXT(tblLaborEntries[[#This Row],[Work date serial]]-WEEKDAY(tblLaborEntries[[#This Row],[Work date serial]],3),"yyyy-mm-dd") -> 2024-12-02 | I10: =DATEVALUE(tblLaborEntries[[#This Row],[Work date]]) -> 45628
A11: LAB-000010 | B11: WP-00006 | C11: TECH-019 | D11: Airframe | E11: 2024-07-11 | F11: 7.2 | G11: 0 | H11: =TEXT(tblLaborEntries[[#This Row],[Work date serial]]-WEEKDAY(tblLaborEntries[[#This Row],[Work date serial]],3),"yyyy-mm-dd") -> 2024-07-08 | I11: =DATEVALUE(tblLaborEntries[[#This Row],[Work date]]) -> 45484
A12: LAB-000011 | B12: WP-00007 | C12: TECH-031 | D12: Airframe | E12: 2024-10-23 | F12: 4.9 | G12: 0 | H12: =TEXT(tblLaborEntries[[#This Row],[Work date serial]]-WEEKDAY(tblLaborEntries[[#This Row],[Work date serial]],3),"yyyy-mm-dd") -> 2024-10-21 | I12: =DATEVALUE(tblLaborEntries[[#This Row],[Work date]]) -> 45588
A13: LAB-000012 | B13: WP-00008 | C13: TECH-033 | D13: Hydraulics | E13: 2025-08-13 | F13: 5.3 | G13: 0 | H13: =TEXT(tblLaborEntries[[#This Row],[Work date serial]]-WEEKDAY(tblLaborEntries[[#This Row],[Work date serial]],3),"yyyy-mm-dd") -> 2025-08-11 | I13: =DATEVALUE(tblLaborEntries[[#This Row],[Work date]]) -> 45882
... A5476: LAB-005475 | B5476: WP-02400 | C5476: TECH-061 | D5476: Airframe | E5476: 2024-08-14 | F5476: 2.2 | G5476: 0 | H5476: =TEXT(tblLaborEntries[[#This Row],[Work date serial]]-WEEKDAY(tblLaborEntries[[#This Row],[Work date serial]],3),"yyyy-mm-dd") -> 2024-08-12 | I5476: =DATEVALUE(tblLaborEntries[[#This Row],[Work date]]) -> 45518

Sheet Technicians
A1: Technician ID | B1: Primary skill | C1: Shift | D1: Start year | E1: Availability factor
A2: TECH-001 | B2: Airframe | C2: Day | D2: 2024 | E2: 0.86677347
A3: TECH-002 | B3: Avionics | C3: Day | D3: 2024 | E3: 0.83847801
A4: TECH-003 | B4: Hydraulics | C4: Day | D4: 2024 | E4: 0.85293262
A5: TECH-004 | B5: Electrical | C5: Swing | D5: 2024 | E5: 0.88714954
A6: TECH-005 | B6: Structures | C6: Day | D6: 2024 | E6: 0.79466289
A7: TECH-006 | B7: Powerplant | C7: Day | D7: 2024 | E7: 0.88049859
A8: TECH-007 | B8: Airframe | C8: Day | D8: 2024 | E8: 0.76131571
A9: TECH-008 | B9: Avionics | C9: Swing | D9: 2024 | E9: 0.77890785
A10: TECH-009 | B10: Hydraulics | C10: Day | D10: 2024 | E10: 0.86591699
A11: TECH-010 | B11: Electrical | C11: Day | D11: 2024 | E11: 0.74483903
A12: TECH-011 | B12: Structures | C12: Day | D12: 2024 | E12: 0.73768907
A13: TECH-012 | B13: Powerplant | C13: Swing | D13: 2024 | E13: 0.83654623
... A76: TECH-075 | B76: Hydraulics | C76: Day | D76: 2024 | E76: 0.73816894

Sheet Parts
A1: Part record ID | B1: Work package ID | C1: Part category | D1: Needed date | E1: Available date | F1: Delay days | G1: Status
A2: PART-00001 | B2: WP-00003 | C2: Valve | D2: 2024-01-31 | E2: 2024-01-31 | F2: 0 | G2: On time
A3: PART-00002 | B3: WP-00005 | C3: Sensor | D3: 2024-12-01 | E3: 2024-12-01 | F3: 0 | G3: On time
A4: PART-00003 | B4: WP-00006 | C4: Fastener kit | D4: 2024-06-29 | E4: 2024-06-29 | F4: 0 | G4: On time
A5: PART-00004 | B5: WP-00008 | C5: Valve | D5: 2025-06-28 | E5: 2025-07-08 | F5: 10 | G5: Delayed
A6: PART-00005 | B6: WP-00009 | C6: Seal kit | D6: 2025-05-15 | E6: 2025-05-15 | F6: 0 | G6: On time
A7: PART-00006 | B7: WP-00015 | C7: Actuator | D7: 2025-08-08 | E7: 2025-08-08 | F7: 0 | G7: On time
A8: PART-00007 | B8: WP-00024 | C8: Harness | D8: 2024-12-26 | E8: 2024-12-26 | F8: 0 | G8: On time
A9: PART-00008 | B9: WP-00025 | C9: Valve | D9: 2024-12-06 | E9: 2024-12-06 | F9: 0 | G9: On time
A10: PART-00009 | B10: WP-00029 | C10: Fastener kit | D10: 2025-04-01 | E10: 2025-04-01 | F10: 0 | G10: On time
A11: PART-00010 | B11: WP-00031 | C11: Valve | D11: 2025-01-22 | E11: 2025-01-22 | F11: 0 | G11: On time
A12: PART-00011 | B12: WP-00032 | C12: Valve | D12: 2025-08-28 | E12: 2025-08-28 | F12: 0 | G12: On time
A13: PART-00012 | B13: WP-00035 | C13: Seal kit | D13: 2024-08-26 | E13: 2024-08-26 | F13: 0 | G13: On time
... A835: PART-00834 | B835: WP-02396 | C835: Sensor | D835: 2025-08-20 | E835: 2025-08-20 | F835: 0 | G835: On time

Sheet Disruptions
A1: Disruption ID | B1: Work package ID | C1: Event type | D1: Event date | E1: Impact days | F1: Cause
A2: DIS-00001 | B2: WP-00008 | C2: Part delay | D2: 2025-06-28 | E2: 10 | F2: Supplier lead time
A3: DIS-00002 | B3: WP-00027 | C3: Equipment unavailable | D3: 2024-08-18 | E3: 2 | F3: Operational event
A4: DIS-00003 | B4: WP-00046 | C4: Equipment unavailable | D4: 2025-10-19 | E4: 2 | F4: Operational event
A5: DIS-00004 | B5: WP-00047 | C5: Part delay | D5: 2025-11-16 | E5: 4 | F5: Supplier lead time
A6: DIS-00005 | B6: WP-00067 | C6: Repeat inspection | D6: 2024-05-21 | E6: 2 | F6: Operational event
A7: DIS-00006 | B7: WP-00071 | C7: Part delay | D7: 2024-05-04 | E7: 10 | F7: Supplier lead time
A8: DIS-00007 | B8: WP-00076 | C8: Equipment unavailable | D8: 2024-09-04 | E8: 2 | F8: Operational event
A9: DIS-00008 | B9: WP-00078 | C9: Part delay | D9: 2024-06-27 | E9: 6 | F9: Supplier lead time
A10: DIS-00009 | B10: WP-00079 | C10: Part delay | D10: 2024-01-26 | E10: 11 | F10: Supplier lead time
A11: DIS-00010 | B11: WP-00087 | C11: Part delay | D11: 2025-03-30 | E11: 12 | F11: Supplier lead time
A12: DIS-00011 | B12: WP-00093 | C12: Technician absence | D12: 2025-01-05 | E12: 2 | F12: Operational event
A13: DIS-00012 | B13: WP-00097 | C13: Part delay | D13: 2024-01-20 | E13: 4 | F13: Supplier lead time
... A302: DIS-00301 | B302: WP-02389 | C302: Part delay | D302: 2025-05-11 | E302: 6 | F302: Supplier lead time

Sheet Task rules
A1: Task type | B1: Work class | C1: Required skill | D1: Baseline hours | E1: Spread driver
A2: Preflight inspection | B2: Inspection | C2: Airframe | D2: 3.2 | E2: 1
A3: Postflight discrepancy review | B3: Inspection | C3: Avionics | D3: 4.8 | E3: 1.5
A4: Instrumentation installation | B4: Modification | C4: Avionics | D4: 15 | E4: 3.3
A5: Sensor calibration | B5: Test support | C5: Avionics | D5: 8 | E5: 2
A6: Hydraulic leak diagnosis | B6: Corrective | C6: Hydraulics | D6: 11 | E6: 3.2
A7: Electrical fault isolation | B7: Corrective | C7: Electrical | D7: 12 | E7: 3.5
A8: Flight control inspection | B8: Inspection | C8: Airframe | D8: 7.5 | E8: 2.1
A9: Structural repair | B9: Corrective | C9: Structures | D9: 22 | E9: 5.2
A10: Software/configuration check | B10: Test support | C10: Avionics | D10: 5.5 | E10: 1.4
A11: Scheduled system service | B11: Preventive | C11: Airframe | D11: 9 | E11: 2
A12: Engine run support | B12: Test support | C12: Powerplant | D12: 13 | E12: 2.7
A13: Fuel system inspection | B13: Inspection | C13: Powerplant | D13: 10 | E13: 2.8

Sheet Weekly history
A2: Weekly maintenance workload
A4: History | B4: 105 consecutive weeks
A5: First week | B5: 2024-01-01
A6: Last week | B6: 2025-12-29
A7: Jobs requested | B7: =SUM(B11:B115) -> 2400
A8: Actual hours for those jobs | B8: =SUM(D11:D115) -> 29351.1
A10: Week of (Monday) | B10: Jobs requested | C10: Estimated hours for requests | D10: Actual hours for requests | E10: Hours booked that week | F10: Urgent jobs requested | G10: Planning forecast hours for requests
A11: 2024-01-01 | B11: =COUNTIFS(tblWorkPackages[Request week (Monday)],A11) -> 16 | C11: =SUMIFS(tblWorkPackages[Estimated labor hours],tblWorkPackages[Request week (Monday)],A11) -> 167.5 | D11: =SUMIFS(tblWorkPackages[Actual labor hours],tblWorkPackages[Request week (Monday)],A11) -> 179.7 | E11: =SUMIFS(tblLaborEntries[Hours booked],tblLaborEntries[Work week (Monday)],A11) -> 99.2 | F11: =COUNTIFS(tblWorkPackages[Request week (Monday)],A11,tblWorkPackages[Priority],"Urgent") -> 0 | G11: =SUMIFS(tblWorkPackages[Planning forecast hours],tblWorkPackages[Request week (Monday)],A11) -> 167.5
A12: 2024-01-08 | B12: =COUNTIFS(tblWorkPackages[Request week (Monday)],A12) -> 21 | C12: =SUMIFS(tblWorkPackages[Estimated labor hours],tblWorkPackages[Request week (Monday)],A12) -> 249.9 | D12: =SUMIFS(tblWorkPackages[Actual labor hours],tblWorkPackages[Request week (Monday)],A12) -> 260 | E12: =SUMIFS(tblLaborEntries[Hours booked],tblLaborEntries[Work week (Monday)],A12) -> 120.5 | F12: =COUNTIFS(tblWorkPackages[Request week (Monday)],A12,tblWorkPackages[Priority],"Urgent") -> 2 | G12: =SUMIFS(tblWorkPackages[Planning forecast hours],tblWorkPackages[Request week (Monday)],A12) -> 249.9
A13: 2024-01-15 | B13: =COUNTIFS(tblWorkPackages[Request week (Monday)],A13) -> 20 | C13: =SUMIFS(tblWorkPackages[Estimated labor hours],tblWorkPackages[Request week (Monday)],A13) -> 222.7 | D13: =SUMIFS(tblWorkPackages[Actual labor hours],tblWorkPackages[Request week (Monday)],A13) -> 224.7 | E13: =SUMIFS(tblLaborEntries[Hours booked],tblLaborEntries[Work week (Monday)],A13) -> 121.4 | F13: =COUNTIFS(tblWorkPackages[Request week (Monday)],A13,tblWorkPackages[Priority],"Urgent") -> 3 | G13: =SUMIFS(tblWorkPackages[Planning forecast hours],tblWorkPackages[Request week (Monday)],A13) -> 222.7
A14: 2024-01-22 | B14: =COUNTIFS(tblWorkPackages[Request week (Monday)],A14) -> 21 | C14: =SUMIFS(tblWorkPackages[Estimated labor hours],tblWorkPackages[Request week (Monday)],A14) -> 227.3 | D14: =SUMIFS(tblWorkPackages[Actual labor hours],tblWorkPackages[Request week (Monday)],A14) -> 245.1 | E14: =SUMIFS(tblLaborEntries[Hours booked],tblLaborEntries[Work week (Monday)],A14) -> 257.3 | F14: =COUNTIFS(tblWorkPackages[Request week (Monday)],A14,tblWorkPackages[Priority],"Urgent") -> 2 | G14: =SUMIFS(tblWorkPackages[Planning forecast hours],tblWorkPackages[Request week (Monday)],A14) -> 227.3
A15: 2024-01-29 | B15: =COUNTIFS(tblWorkPackages[Request week (Monday)],A15) -> 22 | C15: =SUMIFS(tblWorkPackages[Estimated labor hours],tblWorkPackages[Request week (Monday)],A15) -> 233.8 | D15: =SUMIFS(tblWorkPackages[Actual labor hours],tblWorkPackages[Request week (Monday)],A15) -> 234.2 | E15: =SUMIFS(tblLaborEntries[Hours booked],tblLaborEntries[Work week (Monday)],A15) -> 86.7 | F15: =COUNTIFS(tblWorkPackages[Request week (Monday)],A15,tblWorkPackages[Priority],"Urgent") -> 3 | G15: =SUMIFS(tblWorkPackages[Planning forecast hours],tblWorkPackages[Request week (Monday)],A15) -> 233.8
